File: UMAT/data/sig_eps_data
#strain.123 (.), stress.123 (MPa), pl. strain.123 (.), equ. stress (MPa), equ. strain (.), peeq (.)
    -0.0000900     0.0003000    -0.0000900     0.0000000    60.0000000     0.0000000     0.0000000     0.0000000     0.0000000    60.0000000     0.0002835     0.0000000
    -0.0001800     0.0006000    -0.0001800     0.0000000   120.0000000     0.0000000     0.0000000     0.0000000     0.0000000   120.0000000     0.0005671     0.0000000
    -0.0002700     0.0009000    -0.0002700     5.6541436   168.6002434     5.7456131    -0.0000368     0.0000741    -0.0000373   162.9003843     0.0008506     0.0000741
    -0.0003600     0.0012000    -0.0003600    25.9559662   188.6033111    25.4407227    -0.0001687     0.0003341    -0.0001654   162.9055778     0.0011342     0.0003341
    -0.0004500     0.0015000    -0.0004500    46.1638776   208.6047621    45.2313603    -0.0003001     0.0005941    -0.0002940   162.9091449     0.0014177     0.0005941
    -0.0001800     0.0006000    -0.0001800     0.0000000   120.0000000     0.0000000     0.0000000     0.0000000     0.0000000   120.0000000     0.0005671     0.0000000
    -0.0002700     0.0009000    -0.0002700     5.6541436   168.6002434     5.7456131    -0.0000368     0.0000741    -0.0000373   162.9003843     0.0008506     0.0000741
    -0.0003600     0.0012000    -0.0003600    25.9559662   188.6033111    25.4407227    -0.0001687     0.0003341    -0.0001654   162.9055778     0.0011342     0.0003341
    -0.0004500     0.0015000    -0.0004500    46.1638776   208.6047621    45.2313603    -0.0003001     0.0005941    -0.0002940   162.9091449     0.0014177     0.0005941